import React from 'react';
import { DatabaseRecord } from '@/types/database/tables';
import { render, screen, fireEvent } from '@testing-library/react';
import ErrorBoundary from '../ErrorBoundary';

// Mock console methods
const mockConsoleError = jest.spyOn(console, 'error').mockImplementation();

// Mock window.location.reload
delete (window as any).location;
window.location = { reload: jest.fn() } as any;

// Component that throws an error
const ThrowError = ({ shouldThrow }: { shouldThrow: boolean }) => {
  if (shouldThrow) {
    throw new Error('Test error');
  }
  return <div>No error</div>;
};

describe('ErrorBoundary', () => {
  beforeEach(() => {
    jest.clearAllMocks();
  });

  afterEach(() => {
    jest.clearAllMocks();
  });

  it('should render children when there is no error', () => {
    render(
      <ErrorBoundary>
        <div>Test content</div>
      </ErrorBoundary>
    );

    expect(screen.getByText('Test content')).toBeInTheDocument();
  });

  it('should catch errors and display error UI', () => {
    render(
      <ErrorBoundary>
        <ThrowError shouldThrow={true} />
      </ErrorBoundary>
    );

    expect(screen.getByText('Something went wrong')).toBeInTheDocument();
    expect(screen.getByText("We're working to fix this issue. Please try again later.")).toBeInTheDocument();
    expect(screen.getByText('Error: Test error')).toBeInTheDocument();
  });

  it('should display reload button when error occurs', () => {
    render(
      <ErrorBoundary>
        <ThrowError shouldThrow={true} />
      </ErrorBoundary>
    );

    const reloadButton = screen.getByText('Reload page');
    expect(reloadButton).toBeInTheDocument();
  });

  it('should reload page when reload button is clicked', () => {
    render(
      <ErrorBoundary>
        <ThrowError shouldThrow={true} />
      </ErrorBoundary>
    );

    const reloadButton = screen.getByText('Reload page');
    fireEvent.click(reloadButton);

    expect(window.location.reload).toHaveBeenCalled();
  });

  it('should log error to console', () => {
    render(
      <ErrorBoundary>
        <ThrowError shouldThrow={true} />
      </ErrorBoundary>
    );

    expect(mockConsoleError).toHaveBeenCalledWith(
      'Error boundary caught an error:',
      expect.any(Error),
      expect.any(Object)
    );
  });

  it('should handle multiple children', () => {
    render(
      <ErrorBoundary>
        <div>Child 1</div>
        <div>Child 2</div>
        <div>Child 3</div>
      </ErrorBoundary>
    );

    expect(screen.getByText('Child 1')).toBeInTheDocument();
    expect(screen.getByText('Child 2')).toBeInTheDocument();
    expect(screen.getByText('Child 3')).toBeInTheDocument();
  });

  it('should handle errors from nested components', () => {
    const NestedComponent = () => {
      throw new Error('Nested error');
    };

    const ParentComponent = () => (
      <div>
        <NestedComponent />
      </div>
    );

    render(
      <ErrorBoundary>
        <ParentComponent />
      </ErrorBoundary>
    );

    expect(screen.getByText('Something went wrong')).toBeInTheDocument();
    expect(screen.getByText('Error: Nested error')).toBeInTheDocument();
  });

  it('should render without children', () => {
    render(<ErrorBoundary><div>Test content</div></ErrorBoundary>);

    // Should not throw and should render nothing
    expect(document.body.firstChild).toBeDefined();
  });

  it('should display custom error messages', () => {
    class CustomError extends Error {
      constructor(message: string) {
        super(message);
        this.name = 'CustomError';
      }
    }

    const ThrowCustomError = () => {
      throw new CustomError('Custom error message');
    };

    render(
      <ErrorBoundary>
        <ThrowCustomError />
      </ErrorBoundary>
    );

    expect(screen.getByText('CustomError: Custom error message')).toBeInTheDocument();
  });

  it('should handle errors during render phase', () => {
    const BrokenComponent = () => {
      // Simulate error during render
      const obj: DatabaseRecord | null = null;
      return <div>{(obj as any)?.nonExistent}</div>;
    };

    render(
      <ErrorBoundary>
        <BrokenComponent />
      </ErrorBoundary>
    );

    expect(screen.getByText('Something went wrong')).toBeInTheDocument();
  });

  it('should apply correct styles to error UI', () => {
    render(
      <ErrorBoundary>
        <ThrowError shouldThrow={true} />
      </ErrorBoundary>
    );

    // Find the container with the correct classes
    const heading = screen.getByText('Something went wrong');
    const container = heading.parentElement?.parentElement;
    expect(container).toHaveClass('w-full', 'max-w-md', 'space-y-8');

    const errorPre = screen.getByText('Error: Test error');
    expect(errorPre).toHaveClass('mt-4', 'overflow-auto', 'rounded-md', 'bg-red-50', 'p-4', 'text-sm', 'text-red-600');

    const reloadButton = screen.getByText('Reload page');
    expect(reloadButton).toHaveClass('inline-flex', 'items-center', 'rounded-md', 'border', 'border-transparent', 'bg-blue-600', 'px-4', 'py-2', 'text-sm', 'font-medium', 'text-white');
  });

  it('should reset error state when receiving new props', () => {
    const { rerender } = render(
      <ErrorBoundary>
        <ThrowError shouldThrow={true} />
      </ErrorBoundary>
    );

    expect(screen.getByText('Something went wrong')).toBeInTheDocument();

    // This would typically be handled by a reset mechanism in a real app
    // For testing, we verify the error boundary maintains its state
    rerender(
      <ErrorBoundary>
        <ThrowError shouldThrow={false} />
      </ErrorBoundary>
    );

    // Error boundary should still show error state
    expect(screen.getByText('Something went wrong')).toBeInTheDocument();
  });

  it('should handle async errors', async () => {
    const AsyncError = () => {
      React.useEffect(() => {
        // In React 18+, errors in useEffect can be caught by error boundaries
        throw new Error('Async error');
      }, []);
      return <div>Loading...</div>;
    };

    // In React 18, errors thrown in useEffect are caught by error boundaries
    render(
      <ErrorBoundary>
        <AsyncError />
      </ErrorBoundary>
    );

    // The error boundary should catch the error from useEffect
    expect(screen.getByText('Something went wrong')).toBeInTheDocument();
    expect(screen.getByText('Error: Async error')).toBeInTheDocument();
  });
});
